[2024-01-08T05:06:24.928+0000] {taskinstance.py:1957} INFO - Dependencies all met for dep_context=non-requeueable deps ti=<TaskInstance: etl_to_datalake.wait_etl_to_dwh_fact_a scheduled__2024-01-07T00:00:00+00:00 [queued]>
[2024-01-08T05:06:24.946+0000] {taskinstance.py:1957} INFO - Dependencies all met for dep_context=requeueable deps ti=<TaskInstance: etl_to_datalake.wait_etl_to_dwh_fact_a scheduled__2024-01-07T00:00:00+00:00 [queued]>
[2024-01-08T05:06:24.947+0000] {taskinstance.py:2171} INFO - Starting attempt 3 of 5
[2024-01-08T05:06:24.974+0000] {taskinstance.py:2192} INFO - Executing <Task(ExternalTaskSensor): wait_etl_to_dwh_fact_a> on 2024-01-07 00:00:00+00:00
[2024-01-08T05:06:24.984+0000] {standard_task_runner.py:60} INFO - Started process 281 to run task
[2024-01-08T05:06:24.991+0000] {standard_task_runner.py:87} INFO - Running: ['***', 'tasks', 'run', 'etl_to_datalake', 'wait_etl_to_dwh_fact_a', 'scheduled__2024-01-07T00:00:00+00:00', '--job-id', '32', '--raw', '--subdir', 'DAGS_FOLDER/etl_to_datalake.py', '--cfg-path', '/tmp/tmp5q80469d']
[2024-01-08T05:06:24.993+0000] {standard_task_runner.py:88} INFO - Job 32: Subtask wait_etl_to_dwh_fact_a
[2024-01-08T05:06:25.108+0000] {task_command.py:423} INFO - Running <TaskInstance: etl_to_datalake.wait_etl_to_dwh_fact_a scheduled__2024-01-07T00:00:00+00:00 [running]> on host 6d1c1d696e23
[2024-01-08T05:06:25.244+0000] {taskinstance.py:2481} INFO - Exporting env vars: AIRFLOW_CTX_DAG_OWNER='***' AIRFLOW_CTX_DAG_ID='etl_to_datalake' AIRFLOW_CTX_TASK_ID='wait_etl_to_dwh_fact_a' AIRFLOW_CTX_EXECUTION_DATE='2024-01-07T00:00:00+00:00' AIRFLOW_CTX_TRY_NUMBER='3' AIRFLOW_CTX_DAG_RUN_ID='scheduled__2024-01-07T00:00:00+00:00'
[2024-01-08T05:06:25.252+0000] {taskinstance.py:2699} ERROR - Task failed with exception
Traceback (most recent call last):
  File "/home/airflow/.local/lib/python3.8/site-packages/airflow/models/taskinstance.py", line 433, in _execute_task
    result = execute_callable(context=context, **execute_callable_kwargs)
  File "/home/airflow/.local/lib/python3.8/site-packages/airflow/sensors/external_task.py", line 334, in execute
    super().execute(context)
  File "/home/airflow/.local/lib/python3.8/site-packages/airflow/sensors/base.py", line 263, in execute
    raise e
  File "/home/airflow/.local/lib/python3.8/site-packages/airflow/sensors/base.py", line 245, in execute
    poke_return = self.poke(context)
  File "/home/airflow/.local/lib/python3.8/site-packages/airflow/utils/session.py", line 79, in wrapper
    return func(*args, session=session, **kwargs)
  File "/home/airflow/.local/lib/python3.8/site-packages/airflow/sensors/external_task.py", line 240, in poke
    dttm_filter = self._get_dttm_filter(context)
  File "/home/airflow/.local/lib/python3.8/site-packages/airflow/sensors/external_task.py", line 227, in _get_dttm_filter
    dttm = context["logical_date"] - self.execution_delta
TypeError: unsupported operand type(s) for -: 'DateTime' and 'str'
[2024-01-08T05:06:25.270+0000] {taskinstance.py:1138} INFO - Marking task as UP_FOR_RETRY. dag_id=etl_to_datalake, task_id=wait_etl_to_dwh_fact_a, execution_date=20240107T000000, start_date=20240108T050624, end_date=20240108T050625
[2024-01-08T05:06:25.288+0000] {standard_task_runner.py:107} ERROR - Failed to execute job 32 for task wait_etl_to_dwh_fact_a (unsupported operand type(s) for -: 'DateTime' and 'str'; 281)
[2024-01-08T05:06:25.340+0000] {local_task_job_runner.py:234} INFO - Task exited with return code 1
[2024-01-08T05:06:25.374+0000] {taskinstance.py:3281} INFO - 0 downstream tasks scheduled from follow-on schedule check
