[2024-01-08T07:47:09.167+0000] {taskinstance.py:1957} INFO - Dependencies all met for dep_context=non-requeueable deps ti=<TaskInstance: etl_to_dwh.wait_etl_to_datalake_table_source_a manual__2024-01-08T07:47:05.494606+00:00 [queued]>
[2024-01-08T07:47:09.189+0000] {taskinstance.py:1957} INFO - Dependencies all met for dep_context=requeueable deps ti=<TaskInstance: etl_to_dwh.wait_etl_to_datalake_table_source_a manual__2024-01-08T07:47:05.494606+00:00 [queued]>
[2024-01-08T07:47:09.189+0000] {taskinstance.py:2171} INFO - Starting attempt 1 of 3
[2024-01-08T07:47:09.219+0000] {taskinstance.py:2192} INFO - Executing <Task(ExternalTaskSensor): wait_etl_to_datalake_table_source_a> on 2024-01-08 07:47:05.494606+00:00
[2024-01-08T07:47:09.230+0000] {standard_task_runner.py:60} INFO - Started process 120 to run task
[2024-01-08T07:47:09.247+0000] {standard_task_runner.py:87} INFO - Running: ['***', 'tasks', 'run', 'etl_to_dwh', 'wait_etl_to_datalake_table_source_a', 'manual__2024-01-08T07:47:05.494606+00:00', '--job-id', '73', '--raw', '--subdir', 'DAGS_FOLDER/etl_to_dwh.py', '--cfg-path', '/tmp/tmpc_7ak5h9']
[2024-01-08T07:47:09.250+0000] {standard_task_runner.py:88} INFO - Job 73: Subtask wait_etl_to_datalake_table_source_a
[2024-01-08T07:47:09.374+0000] {task_command.py:423} INFO - Running <TaskInstance: etl_to_dwh.wait_etl_to_datalake_table_source_a manual__2024-01-08T07:47:05.494606+00:00 [running]> on host 6d1c1d696e23
[2024-01-08T07:47:09.549+0000] {taskinstance.py:2481} INFO - Exporting env vars: AIRFLOW_CTX_DAG_OWNER='***' AIRFLOW_CTX_DAG_ID='etl_to_dwh' AIRFLOW_CTX_TASK_ID='wait_etl_to_datalake_table_source_a' AIRFLOW_CTX_EXECUTION_DATE='2024-01-08T07:47:05.494606+00:00' AIRFLOW_CTX_TRY_NUMBER='1' AIRFLOW_CTX_DAG_RUN_ID='manual__2024-01-08T07:47:05.494606+00:00'
[2024-01-08T07:47:09.555+0000] {external_task.py:244} INFO - Poking for tasks ['table_source_a'] in dag etl_to_datalake on 2024-01-08T05:47:05.494606+00:00 ... 
[2024-01-08T07:47:49.680+0000] {local_task_job_runner.py:302} WARNING - State of this instance has been externally set to failed. Terminating instance.
[2024-01-08T07:47:49.684+0000] {process_utils.py:131} INFO - Sending 15 to group 120. PIDs of all processes in the group: [120]
[2024-01-08T07:47:49.684+0000] {process_utils.py:86} INFO - Sending the signal 15 to group 120
[2024-01-08T07:47:49.685+0000] {taskinstance.py:2451} ERROR - Received SIGTERM. Terminating subprocesses.
[2024-01-08T07:47:49.779+0000] {process_utils.py:79} INFO - Process psutil.Process(pid=120, status='terminated', exitcode=0, started='07:47:08') (120) terminated with exit code 0
