[2024-03-18T09:18:04.276+0000] {taskinstance.py:1957} INFO - Dependencies all met for dep_context=non-requeueable deps ti=<TaskInstance: etl_to_datalake.table_source_b manual__2024-03-18T09:18:01.182706+00:00 [queued]>
[2024-03-18T09:18:04.293+0000] {taskinstance.py:1957} INFO - Dependencies all met for dep_context=requeueable deps ti=<TaskInstance: etl_to_datalake.table_source_b manual__2024-03-18T09:18:01.182706+00:00 [queued]>
[2024-03-18T09:18:04.294+0000] {taskinstance.py:2171} INFO - Starting attempt 1 of 3
[2024-03-18T09:18:04.323+0000] {taskinstance.py:2192} INFO - Executing <Task(PythonOperator): table_source_b> on 2024-03-18 09:18:01.182706+00:00
[2024-03-18T09:18:04.337+0000] {standard_task_runner.py:60} INFO - Started process 139 to run task
[2024-03-18T09:18:04.345+0000] {standard_task_runner.py:87} INFO - Running: ['***', 'tasks', 'run', 'etl_to_datalake', 'table_source_b', 'manual__2024-03-18T09:18:01.182706+00:00', '--job-id', '11', '--raw', '--subdir', 'DAGS_FOLDER/etl_to_datalake.py', '--cfg-path', '/tmp/tmpkkyimw8s']
[2024-03-18T09:18:04.350+0000] {standard_task_runner.py:88} INFO - Job 11: Subtask table_source_b
[2024-03-18T09:18:04.450+0000] {task_command.py:423} INFO - Running <TaskInstance: etl_to_datalake.table_source_b manual__2024-03-18T09:18:01.182706+00:00 [running]> on host bb65d6418542
[2024-03-18T09:18:04.613+0000] {taskinstance.py:2481} INFO - Exporting env vars: AIRFLOW_CTX_DAG_OWNER='***' AIRFLOW_CTX_DAG_ID='etl_to_datalake' AIRFLOW_CTX_TASK_ID='table_source_b' AIRFLOW_CTX_EXECUTION_DATE='2024-03-18T09:18:01.182706+00:00' AIRFLOW_CTX_TRY_NUMBER='1' AIRFLOW_CTX_DAG_RUN_ID='manual__2024-03-18T09:18:01.182706+00:00'
[2024-03-18T09:18:04.673+0000] {taskinstance.py:2699} ERROR - Task failed with exception
Traceback (most recent call last):
  File "/home/airflow/.local/lib/python3.8/site-packages/airflow/models/taskinstance.py", line 433, in _execute_task
    result = execute_callable(context=context, **execute_callable_kwargs)
  File "/home/airflow/.local/lib/python3.8/site-packages/airflow/operators/python.py", line 199, in execute
    return_value = self.execute_callable()
  File "/home/airflow/.local/lib/python3.8/site-packages/airflow/operators/python.py", line 216, in execute_callable
    return self.python_callable(*self.op_args, **self.op_kwargs)
  File "/opt/airflow/dags/etl_to_datalake.py", line 76, in process_datalake
    load_query_result_to_bq(dict_config["sql"], dict_config["write_disposition"],
  File "/opt/airflow/dags/etl_to_datalake.py", line 56, in load_query_result_to_bq
    raise e
  File "/opt/airflow/dags/etl_to_datalake.py", line 42, in load_query_result_to_bq
    bq_client = init_bq_client()
  File "/opt/airflow/dags/etl_to_datalake.py", line 31, in init_bq_client
    raise e
  File "/opt/airflow/dags/etl_to_datalake.py", line 23, in init_bq_client
    conn = Connection.get_connection_from_secrets(conn_id='dwh-creds')
  File "/home/airflow/.local/lib/python3.8/site-packages/airflow/models/connection.py", line 479, in get_connection_from_secrets
    raise AirflowNotFoundException(f"The conn_id `{conn_id}` isn't defined")
airflow.exceptions.AirflowNotFoundException: The conn_id `dwh-creds` isn't defined
[2024-03-18T09:18:04.681+0000] {taskinstance.py:1138} INFO - Marking task as UP_FOR_RETRY. dag_id=etl_to_datalake, task_id=table_source_b, execution_date=20240318T091801, start_date=20240318T091804, end_date=20240318T091804
[2024-03-18T09:18:04.700+0000] {standard_task_runner.py:107} ERROR - Failed to execute job 11 for task table_source_b (The conn_id `dwh-creds` isn't defined; 139)
[2024-03-18T09:18:04.722+0000] {local_task_job_runner.py:234} INFO - Task exited with return code 1
[2024-03-18T09:18:04.748+0000] {taskinstance.py:3281} INFO - 0 downstream tasks scheduled from follow-on schedule check
