[2023-12-28T08:35:29.740+0000] {taskinstance.py:1957} INFO - Dependencies all met for dep_context=non-requeueable deps ti=<TaskInstance: etl_to_datalake.table_source_a scheduled__2023-12-27T00:00:00+00:00 [queued]>
[2023-12-28T08:35:29.747+0000] {taskinstance.py:1957} INFO - Dependencies all met for dep_context=requeueable deps ti=<TaskInstance: etl_to_datalake.table_source_a scheduled__2023-12-27T00:00:00+00:00 [queued]>
[2023-12-28T08:35:29.748+0000] {taskinstance.py:2171} INFO - Starting attempt 10 of 12
[2023-12-28T08:35:29.755+0000] {taskinstance.py:2192} INFO - Executing <Task(PythonOperator): table_source_a> on 2023-12-27 00:00:00+00:00
[2023-12-28T08:35:29.764+0000] {standard_task_runner.py:60} INFO - Started process 472 to run task
[2023-12-28T08:35:29.768+0000] {standard_task_runner.py:87} INFO - Running: ['***', 'tasks', 'run', 'etl_to_datalake', 'table_source_a', 'scheduled__2023-12-27T00:00:00+00:00', '--job-id', '24', '--raw', '--subdir', 'DAGS_FOLDER/etl_to_datalake.py', '--cfg-path', '/tmp/tmpa5_jc3mi']
[2023-12-28T08:35:29.770+0000] {standard_task_runner.py:88} INFO - Job 24: Subtask table_source_a
[2023-12-28T08:35:29.843+0000] {task_command.py:423} INFO - Running <TaskInstance: etl_to_datalake.table_source_a scheduled__2023-12-27T00:00:00+00:00 [running]> on host 64bb4a2d8189
[2023-12-28T08:35:29.989+0000] {taskinstance.py:2481} INFO - Exporting env vars: AIRFLOW_CTX_DAG_OWNER='***' AIRFLOW_CTX_DAG_ID='etl_to_datalake' AIRFLOW_CTX_TASK_ID='table_source_a' AIRFLOW_CTX_EXECUTION_DATE='2023-12-27T00:00:00+00:00' AIRFLOW_CTX_TRY_NUMBER='10' AIRFLOW_CTX_DAG_RUN_ID='scheduled__2023-12-27T00:00:00+00:00'
[2023-12-28T08:35:30.020+0000] {connection.py:234} WARNING - Connection schemes (type: google_cloud_platform) shall not contain '_' according to RFC3986.
[2023-12-28T08:35:30.029+0000] {logging_mixin.py:188} INFO - conn: dwh-creds
[2023-12-28T08:35:30.029+0000] {logging_mixin.py:188} INFO - json_key: ***
[2023-12-28T08:35:30.036+0000] {taskinstance.py:2699} ERROR - Task failed with exception
Traceback (most recent call last):
  File "/home/airflow/.local/lib/python3.8/site-packages/airflow/models/taskinstance.py", line 433, in _execute_task
    result = execute_callable(context=context, **execute_callable_kwargs)
  File "/home/airflow/.local/lib/python3.8/site-packages/airflow/operators/python.py", line 199, in execute
    return_value = self.execute_callable()
  File "/home/airflow/.local/lib/python3.8/site-packages/airflow/operators/python.py", line 216, in execute_callable
    return self.python_callable(*self.op_args, **self.op_kwargs)
  File "/opt/airflow/dags/etl_to_datalake.py", line 85, in process_datalake
    load_query_result_to_bq(dict_config["sql"], dict_config["write_disposition"],
  File "/opt/airflow/dags/etl_to_datalake.py", line 61, in load_query_result_to_bq
    raise e
  File "/opt/airflow/dags/etl_to_datalake.py", line 47, in load_query_result_to_bq
    bq_client = init_bq_client()
  File "/opt/airflow/dags/etl_to_datalake.py", line 36, in init_bq_client
    service_account_json)
NameError: name 'service_account_json' is not defined
[2023-12-28T08:35:30.055+0000] {taskinstance.py:1138} INFO - Marking task as UP_FOR_RETRY. dag_id=etl_to_datalake, task_id=table_source_a, execution_date=20231227T000000, start_date=20231228T083529, end_date=20231228T083530
[2023-12-28T08:35:30.077+0000] {standard_task_runner.py:107} ERROR - Failed to execute job 24 for task table_source_a (name 'service_account_json' is not defined; 472)
[2023-12-28T08:35:30.110+0000] {local_task_job_runner.py:234} INFO - Task exited with return code 1
[2023-12-28T08:35:30.145+0000] {taskinstance.py:3281} INFO - 0 downstream tasks scheduled from follow-on schedule check
