[2023-12-28T08:39:22.800+0000] {taskinstance.py:1957} INFO - Dependencies all met for dep_context=non-requeueable deps ti=<TaskInstance: etl_to_datalake.table_source_a scheduled__2023-12-27T00:00:00+00:00 [queued]>
[2023-12-28T08:39:22.805+0000] {taskinstance.py:1957} INFO - Dependencies all met for dep_context=requeueable deps ti=<TaskInstance: etl_to_datalake.table_source_a scheduled__2023-12-27T00:00:00+00:00 [queued]>
[2023-12-28T08:39:22.805+0000] {taskinstance.py:2171} INFO - Starting attempt 12 of 14
[2023-12-28T08:39:22.811+0000] {taskinstance.py:2192} INFO - Executing <Task(PythonOperator): table_source_a> on 2023-12-27 00:00:00+00:00
[2023-12-28T08:39:22.825+0000] {standard_task_runner.py:60} INFO - Started process 534 to run task
[2023-12-28T08:39:22.829+0000] {standard_task_runner.py:87} INFO - Running: ['***', 'tasks', 'run', 'etl_to_datalake', 'table_source_a', 'scheduled__2023-12-27T00:00:00+00:00', '--job-id', '26', '--raw', '--subdir', 'DAGS_FOLDER/etl_to_datalake.py', '--cfg-path', '/tmp/tmp14od335q']
[2023-12-28T08:39:22.830+0000] {standard_task_runner.py:88} INFO - Job 26: Subtask table_source_a
[2023-12-28T08:39:22.895+0000] {task_command.py:423} INFO - Running <TaskInstance: etl_to_datalake.table_source_a scheduled__2023-12-27T00:00:00+00:00 [running]> on host 64bb4a2d8189
[2023-12-28T08:39:23.008+0000] {taskinstance.py:2481} INFO - Exporting env vars: AIRFLOW_CTX_DAG_OWNER='***' AIRFLOW_CTX_DAG_ID='etl_to_datalake' AIRFLOW_CTX_TASK_ID='table_source_a' AIRFLOW_CTX_EXECUTION_DATE='2023-12-27T00:00:00+00:00' AIRFLOW_CTX_TRY_NUMBER='12' AIRFLOW_CTX_DAG_RUN_ID='scheduled__2023-12-27T00:00:00+00:00'
[2023-12-28T08:39:23.050+0000] {connection.py:234} WARNING - Connection schemes (type: google_cloud_platform) shall not contain '_' according to RFC3986.
[2023-12-28T08:39:23.054+0000] {taskinstance.py:2699} ERROR - Task failed with exception
Traceback (most recent call last):
  File "/home/airflow/.local/lib/python3.8/site-packages/airflow/models/taskinstance.py", line 433, in _execute_task
    result = execute_callable(context=context, **execute_callable_kwargs)
  File "/home/airflow/.local/lib/python3.8/site-packages/airflow/operators/python.py", line 199, in execute
    return_value = self.execute_callable()
  File "/home/airflow/.local/lib/python3.8/site-packages/airflow/operators/python.py", line 216, in execute_callable
    return self.python_callable(*self.op_args, **self.op_kwargs)
  File "/opt/airflow/dags/etl_to_datalake.py", line 79, in process_datalake
    load_query_result_to_bq(dict_config["sql"], dict_config["write_disposition"],
  File "/opt/airflow/dags/etl_to_datalake.py", line 55, in load_query_result_to_bq
    raise e
  File "/opt/airflow/dags/etl_to_datalake.py", line 41, in load_query_result_to_bq
    bq_client = init_bq_client()
  File "/opt/airflow/dags/etl_to_datalake.py", line 29, in init_bq_client
    credentials = service_account.Credentials.from_service_account_info(
  File "/home/airflow/.local/lib/python3.8/site-packages/google/oauth2/service_account.py", line 240, in from_service_account_info
    signer = _service_account_info.from_dict(
  File "/home/airflow/.local/lib/python3.8/site-packages/google/auth/_service_account_info.py", line 47, in from_dict
    missing = keys_needed.difference(data.keys())
AttributeError: 'str' object has no attribute 'keys'
[2023-12-28T08:39:23.063+0000] {taskinstance.py:1138} INFO - Marking task as UP_FOR_RETRY. dag_id=etl_to_datalake, task_id=table_source_a, execution_date=20231227T000000, start_date=20231228T083922, end_date=20231228T083923
[2023-12-28T08:39:23.069+0000] {standard_task_runner.py:107} ERROR - Failed to execute job 26 for task table_source_a ('str' object has no attribute 'keys'; 534)
[2023-12-28T08:39:23.089+0000] {local_task_job_runner.py:234} INFO - Task exited with return code 1
[2023-12-28T08:39:23.101+0000] {taskinstance.py:3281} INFO - 0 downstream tasks scheduled from follow-on schedule check
