[2023-12-28T09:07:59.601+0000] {taskinstance.py:1957} INFO - Dependencies all met for dep_context=non-requeueable deps ti=<TaskInstance: etl_to_datalake.table_source_a scheduled__2023-12-27T00:00:00+00:00 [queued]>
[2023-12-28T09:07:59.605+0000] {taskinstance.py:1957} INFO - Dependencies all met for dep_context=requeueable deps ti=<TaskInstance: etl_to_datalake.table_source_a scheduled__2023-12-27T00:00:00+00:00 [queued]>
[2023-12-28T09:07:59.606+0000] {taskinstance.py:2171} INFO - Starting attempt 25 of 27
[2023-12-28T09:07:59.612+0000] {taskinstance.py:2192} INFO - Executing <Task(PythonOperator): table_source_a> on 2023-12-27 00:00:00+00:00
[2023-12-28T09:07:59.619+0000] {standard_task_runner.py:60} INFO - Started process 997 to run task
[2023-12-28T09:07:59.625+0000] {standard_task_runner.py:87} INFO - Running: ['***', 'tasks', 'run', 'etl_to_datalake', 'table_source_a', 'scheduled__2023-12-27T00:00:00+00:00', '--job-id', '39', '--raw', '--subdir', 'DAGS_FOLDER/etl_to_datalake.py', '--cfg-path', '/tmp/tmp08wfwugh']
[2023-12-28T09:07:59.627+0000] {standard_task_runner.py:88} INFO - Job 39: Subtask table_source_a
[2023-12-28T09:07:59.682+0000] {task_command.py:423} INFO - Running <TaskInstance: etl_to_datalake.table_source_a scheduled__2023-12-27T00:00:00+00:00 [running]> on host 64bb4a2d8189
[2023-12-28T09:07:59.799+0000] {taskinstance.py:2481} INFO - Exporting env vars: AIRFLOW_CTX_DAG_OWNER='***' AIRFLOW_CTX_DAG_ID='etl_to_datalake' AIRFLOW_CTX_TASK_ID='table_source_a' AIRFLOW_CTX_EXECUTION_DATE='2023-12-27T00:00:00+00:00' AIRFLOW_CTX_TRY_NUMBER='25' AIRFLOW_CTX_DAG_RUN_ID='scheduled__2023-12-27T00:00:00+00:00'
[2023-12-28T09:08:01.770+0000] {taskinstance.py:2699} ERROR - Task failed with exception
Traceback (most recent call last):
  File "/home/airflow/.local/lib/python3.8/site-packages/airflow/models/taskinstance.py", line 433, in _execute_task
    result = execute_callable(context=context, **execute_callable_kwargs)
  File "/home/airflow/.local/lib/python3.8/site-packages/airflow/operators/python.py", line 199, in execute
    return_value = self.execute_callable()
  File "/home/airflow/.local/lib/python3.8/site-packages/airflow/operators/python.py", line 216, in execute_callable
    return self.python_callable(*self.op_args, **self.op_kwargs)
  File "/opt/airflow/dags/etl_to_datalake.py", line 80, in process_datalake
    load_query_result_to_bq(dict_config["sql"], dict_config["write_disposition"],
  File "/opt/airflow/dags/etl_to_datalake.py", line 62, in load_query_result_to_bq
    raise e
  File "/opt/airflow/dags/etl_to_datalake.py", line 59, in load_query_result_to_bq
    query_job.result()
  File "/home/airflow/.local/lib/python3.8/site-packages/google/cloud/bigquery/job/query.py", line 1595, in result
    do_get_result()
  File "/home/airflow/.local/lib/python3.8/site-packages/google/api_core/retry.py", line 372, in retry_wrapped_func
    return retry_target(
  File "/home/airflow/.local/lib/python3.8/site-packages/google/api_core/retry.py", line 207, in retry_target
    result = target()
  File "/home/airflow/.local/lib/python3.8/site-packages/google/cloud/bigquery/job/query.py", line 1584, in do_get_result
    super(QueryJob, self).result(retry=retry, timeout=timeout)
  File "/home/airflow/.local/lib/python3.8/site-packages/google/cloud/bigquery/job/base.py", line 952, in result
    return super(_AsyncJob, self).result(timeout=timeout, **kwargs)
  File "/home/airflow/.local/lib/python3.8/site-packages/google/api_core/future/polling.py", line 261, in result
    raise self._exception
google.api_core.exceptions.BadRequest: 400 The field specified for partitioning cannot be found in the schema.

Location: US
Job ID: e6eff13d-0eeb-4d10-b331-ad91c1602fc3

[2023-12-28T09:08:01.875+0000] {taskinstance.py:1138} INFO - Marking task as UP_FOR_RETRY. dag_id=etl_to_datalake, task_id=table_source_a, execution_date=20231227T000000, start_date=20231228T090759, end_date=20231228T090801
[2023-12-28T09:08:01.950+0000] {standard_task_runner.py:107} ERROR - Failed to execute job 39 for task table_source_a (400 The field specified for partitioning cannot be found in the schema.

Location: US
Job ID: e6eff13d-0eeb-4d10-b331-ad91c1602fc3
; 997)
[2023-12-28T09:08:01.995+0000] {local_task_job_runner.py:234} INFO - Task exited with return code 1
[2023-12-28T09:08:02.050+0000] {taskinstance.py:3281} INFO - 0 downstream tasks scheduled from follow-on schedule check
