[2023-12-28T08:17:49.069+0000] {taskinstance.py:1957} INFO - Dependencies all met for dep_context=non-requeueable deps ti=<TaskInstance: etl_to_datalake.table_source_a scheduled__2023-12-27T00:00:00+00:00 [queued]>
[2023-12-28T08:17:49.110+0000] {taskinstance.py:1957} INFO - Dependencies all met for dep_context=requeueable deps ti=<TaskInstance: etl_to_datalake.table_source_a scheduled__2023-12-27T00:00:00+00:00 [queued]>
[2023-12-28T08:17:49.110+0000] {taskinstance.py:2171} INFO - Starting attempt 3 of 5
[2023-12-28T08:17:49.137+0000] {taskinstance.py:2192} INFO - Executing <Task(PythonOperator): table_source_a> on 2023-12-27 00:00:00+00:00
[2023-12-28T08:17:49.152+0000] {standard_task_runner.py:60} INFO - Started process 186 to run task
[2023-12-28T08:17:49.157+0000] {standard_task_runner.py:87} INFO - Running: ['***', 'tasks', 'run', 'etl_to_datalake', 'table_source_a', 'scheduled__2023-12-27T00:00:00+00:00', '--job-id', '17', '--raw', '--subdir', 'DAGS_FOLDER/etl_to_datalake.py', '--cfg-path', '/tmp/tmpc090ijv4']
[2023-12-28T08:17:49.158+0000] {standard_task_runner.py:88} INFO - Job 17: Subtask table_source_a
[2023-12-28T08:17:49.321+0000] {task_command.py:423} INFO - Running <TaskInstance: etl_to_datalake.table_source_a scheduled__2023-12-27T00:00:00+00:00 [running]> on host 64bb4a2d8189
[2023-12-28T08:17:49.418+0000] {taskinstance.py:2481} INFO - Exporting env vars: AIRFLOW_CTX_DAG_OWNER='***' AIRFLOW_CTX_DAG_ID='etl_to_datalake' AIRFLOW_CTX_TASK_ID='table_source_a' AIRFLOW_CTX_EXECUTION_DATE='2023-12-27T00:00:00+00:00' AIRFLOW_CTX_TRY_NUMBER='3' AIRFLOW_CTX_DAG_RUN_ID='scheduled__2023-12-27T00:00:00+00:00'
[2023-12-28T08:17:49.424+0000] {taskinstance.py:2699} ERROR - Task failed with exception
Traceback (most recent call last):
  File "/home/airflow/.local/lib/python3.8/site-packages/airflow/models/taskinstance.py", line 433, in _execute_task
    result = execute_callable(context=context, **execute_callable_kwargs)
  File "/home/airflow/.local/lib/python3.8/site-packages/airflow/operators/python.py", line 199, in execute
    return_value = self.execute_callable()
  File "/home/airflow/.local/lib/python3.8/site-packages/airflow/operators/python.py", line 216, in execute_callable
    return self.python_callable(*self.op_args, **self.op_kwargs)
  File "/opt/airflow/dags/etl_to_datalake.py", line 68, in process_datalake
    dict_config["destination_table"] = config_yaml.get("destination_table")
AttributeError: 'generator' object has no attribute 'get'
[2023-12-28T08:17:49.434+0000] {taskinstance.py:1138} INFO - Marking task as UP_FOR_RETRY. dag_id=etl_to_datalake, task_id=table_source_a, execution_date=20231227T000000, start_date=20231228T081749, end_date=20231228T081749
[2023-12-28T08:17:49.440+0000] {standard_task_runner.py:107} ERROR - Failed to execute job 17 for task table_source_a ('generator' object has no attribute 'get'; 186)
[2023-12-28T08:17:49.452+0000] {local_task_job_runner.py:234} INFO - Task exited with return code 1
[2023-12-28T08:17:49.470+0000] {taskinstance.py:3281} INFO - 0 downstream tasks scheduled from follow-on schedule check
