[2023-12-28T10:15:36.795+0000] {taskinstance.py:1957} INFO - Dependencies all met for dep_context=non-requeueable deps ti=<TaskInstance: etl_to_datalake.table_source_b manual__2023-12-28T10:15:30.338275+00:00 [queued]>
[2023-12-28T10:15:36.813+0000] {taskinstance.py:1957} INFO - Dependencies all met for dep_context=requeueable deps ti=<TaskInstance: etl_to_datalake.table_source_b manual__2023-12-28T10:15:30.338275+00:00 [queued]>
[2023-12-28T10:15:36.814+0000] {taskinstance.py:2171} INFO - Starting attempt 1 of 3
[2023-12-28T10:15:36.827+0000] {taskinstance.py:2192} INFO - Executing <Task(PythonOperator): table_source_b> on 2023-12-28 10:15:30.338275+00:00
[2023-12-28T10:15:36.843+0000] {standard_task_runner.py:60} INFO - Started process 712 to run task
[2023-12-28T10:15:36.883+0000] {standard_task_runner.py:87} INFO - Running: ['***', 'tasks', 'run', 'etl_to_datalake', 'table_source_b', 'manual__2023-12-28T10:15:30.338275+00:00', '--job-id', '50', '--raw', '--subdir', 'DAGS_FOLDER/etl_to_datalake.py', '--cfg-path', '/tmp/tmpwct4c64v']
[2023-12-28T10:15:36.886+0000] {standard_task_runner.py:88} INFO - Job 50: Subtask table_source_b
[2023-12-28T10:15:37.053+0000] {task_command.py:423} INFO - Running <TaskInstance: etl_to_datalake.table_source_b manual__2023-12-28T10:15:30.338275+00:00 [running]> on host 64bb4a2d8189
[2023-12-28T10:15:37.406+0000] {taskinstance.py:2481} INFO - Exporting env vars: AIRFLOW_CTX_DAG_OWNER='***' AIRFLOW_CTX_DAG_ID='etl_to_datalake' AIRFLOW_CTX_TASK_ID='table_source_b' AIRFLOW_CTX_EXECUTION_DATE='2023-12-28T10:15:30.338275+00:00' AIRFLOW_CTX_TRY_NUMBER='1' AIRFLOW_CTX_DAG_RUN_ID='manual__2023-12-28T10:15:30.338275+00:00'
[2023-12-28T10:15:37.460+0000] {logging_mixin.py:188} INFO - ----DEBUG query:
SELECT DATE(last_update_date) AS partition_date,
       unique_key,
       complaint_description,
       SOURCE
FROM `bigquery-public-data.austin_311.311_service_requests`
ORDER BY 1 DESC
[2023-12-28T10:15:37.565+0000] {connection.py:234} WARNING - Connection schemes (type: google_cloud_platform) shall not contain '_' according to RFC3986.
[2023-12-28T10:15:39.572+0000] {taskinstance.py:2699} ERROR - Task failed with exception
Traceback (most recent call last):
  File "/home/airflow/.local/lib/python3.8/site-packages/airflow/models/taskinstance.py", line 433, in _execute_task
    result = execute_callable(context=context, **execute_callable_kwargs)
  File "/home/airflow/.local/lib/python3.8/site-packages/airflow/operators/python.py", line 199, in execute
    return_value = self.execute_callable()
  File "/home/airflow/.local/lib/python3.8/site-packages/airflow/operators/python.py", line 216, in execute_callable
    return self.python_callable(*self.op_args, **self.op_kwargs)
  File "/opt/airflow/dags/etl_to_datalake.py", line 74, in process_datalake
    load_query_result_to_bq(dict_config["sql"], dict_config["write_disposition"],
  File "/opt/airflow/dags/etl_to_datalake.py", line 56, in load_query_result_to_bq
    raise e
  File "/opt/airflow/dags/etl_to_datalake.py", line 51, in load_query_result_to_bq
    query_job_res = query_job.result()
  File "/home/airflow/.local/lib/python3.8/site-packages/google/cloud/bigquery/job/query.py", line 1595, in result
    do_get_result()
  File "/home/airflow/.local/lib/python3.8/site-packages/google/api_core/retry.py", line 372, in retry_wrapped_func
    return retry_target(
  File "/home/airflow/.local/lib/python3.8/site-packages/google/api_core/retry.py", line 207, in retry_target
    result = target()
  File "/home/airflow/.local/lib/python3.8/site-packages/google/cloud/bigquery/job/query.py", line 1584, in do_get_result
    super(QueryJob, self).result(retry=retry, timeout=timeout)
  File "/home/airflow/.local/lib/python3.8/site-packages/google/cloud/bigquery/job/base.py", line 952, in result
    return super(_AsyncJob, self).result(timeout=timeout, **kwargs)
  File "/home/airflow/.local/lib/python3.8/site-packages/google/api_core/future/polling.py", line 261, in result
    raise self._exception
google.api_core.exceptions.BadRequest: 400 Result of ORDER BY queries cannot be partitioned by field 'partition_date'

Location: US
Job ID: f3d5e854-2a80-4be1-aa5c-92c88e20fb6d

[2023-12-28T10:15:39.843+0000] {taskinstance.py:1138} INFO - Marking task as UP_FOR_RETRY. dag_id=etl_to_datalake, task_id=table_source_b, execution_date=20231228T101530, start_date=20231228T101536, end_date=20231228T101539
[2023-12-28T10:15:40.071+0000] {standard_task_runner.py:107} ERROR - Failed to execute job 50 for task table_source_b (400 Result of ORDER BY queries cannot be partitioned by field 'partition_date'

Location: US
Job ID: f3d5e854-2a80-4be1-aa5c-92c88e20fb6d
; 712)
[2023-12-28T10:15:40.119+0000] {local_task_job_runner.py:234} INFO - Task exited with return code 1
[2023-12-28T10:15:40.179+0000] {taskinstance.py:3281} INFO - 0 downstream tasks scheduled from follow-on schedule check
