[2024-01-08T06:37:39.926+0000] {taskinstance.py:1957} INFO - Dependencies all met for dep_context=non-requeueable deps ti=<TaskInstance: etl_to_dwh.wait_etl_to_datalake_table_source_a scheduled__2024-01-07T02:00:00+00:00 [queued]>
[2024-01-08T06:37:39.936+0000] {taskinstance.py:1957} INFO - Dependencies all met for dep_context=requeueable deps ti=<TaskInstance: etl_to_dwh.wait_etl_to_datalake_table_source_a scheduled__2024-01-07T02:00:00+00:00 [queued]>
[2024-01-08T06:37:39.937+0000] {taskinstance.py:2171} INFO - Starting attempt 3 of 5
[2024-01-08T06:37:39.957+0000] {taskinstance.py:2192} INFO - Executing <Task(ExternalTaskSensor): wait_etl_to_datalake_table_source_a> on 2024-01-07 02:00:00+00:00
[2024-01-08T06:37:39.968+0000] {standard_task_runner.py:60} INFO - Started process 126 to run task
[2024-01-08T06:37:39.973+0000] {standard_task_runner.py:87} INFO - Running: ['***', 'tasks', 'run', 'etl_to_dwh', 'wait_etl_to_datalake_table_source_a', 'scheduled__2024-01-07T02:00:00+00:00', '--job-id', '45', '--raw', '--subdir', 'DAGS_FOLDER/etl_to_dwh.py', '--cfg-path', '/tmp/tmpflv944nj']
[2024-01-08T06:37:39.974+0000] {standard_task_runner.py:88} INFO - Job 45: Subtask wait_etl_to_datalake_table_source_a
[2024-01-08T06:37:40.042+0000] {task_command.py:423} INFO - Running <TaskInstance: etl_to_dwh.wait_etl_to_datalake_table_source_a scheduled__2024-01-07T02:00:00+00:00 [running]> on host 6d1c1d696e23
[2024-01-08T06:37:40.166+0000] {taskinstance.py:2481} INFO - Exporting env vars: AIRFLOW_CTX_DAG_OWNER='***' AIRFLOW_CTX_DAG_ID='etl_to_dwh' AIRFLOW_CTX_TASK_ID='wait_etl_to_datalake_table_source_a' AIRFLOW_CTX_EXECUTION_DATE='2024-01-07T02:00:00+00:00' AIRFLOW_CTX_TRY_NUMBER='3' AIRFLOW_CTX_DAG_RUN_ID='scheduled__2024-01-07T02:00:00+00:00'
[2024-01-08T06:37:40.171+0000] {taskinstance.py:2699} ERROR - Task failed with exception
Traceback (most recent call last):
  File "/home/airflow/.local/lib/python3.8/site-packages/airflow/models/taskinstance.py", line 433, in _execute_task
    result = execute_callable(context=context, **execute_callable_kwargs)
  File "/home/airflow/.local/lib/python3.8/site-packages/airflow/sensors/external_task.py", line 334, in execute
    super().execute(context)
  File "/home/airflow/.local/lib/python3.8/site-packages/airflow/sensors/base.py", line 263, in execute
    raise e
  File "/home/airflow/.local/lib/python3.8/site-packages/airflow/sensors/base.py", line 245, in execute
    poke_return = self.poke(context)
  File "/home/airflow/.local/lib/python3.8/site-packages/airflow/utils/session.py", line 79, in wrapper
    return func(*args, session=session, **kwargs)
  File "/home/airflow/.local/lib/python3.8/site-packages/airflow/sensors/external_task.py", line 240, in poke
    dttm_filter = self._get_dttm_filter(context)
  File "/home/airflow/.local/lib/python3.8/site-packages/airflow/sensors/external_task.py", line 227, in _get_dttm_filter
    dttm = context["logical_date"] - self.execution_delta
TypeError: unsupported operand type(s) for -: 'DateTime' and 'str'
[2024-01-08T06:37:40.183+0000] {taskinstance.py:1138} INFO - Marking task as UP_FOR_RETRY. dag_id=etl_to_dwh, task_id=wait_etl_to_datalake_table_source_a, execution_date=20240107T020000, start_date=20240108T063739, end_date=20240108T063740
[2024-01-08T06:37:40.204+0000] {standard_task_runner.py:107} ERROR - Failed to execute job 45 for task wait_etl_to_datalake_table_source_a (unsupported operand type(s) for -: 'DateTime' and 'str'; 126)
[2024-01-08T06:37:40.226+0000] {local_task_job_runner.py:234} INFO - Task exited with return code 1
[2024-01-08T06:37:40.260+0000] {taskinstance.py:3281} INFO - 0 downstream tasks scheduled from follow-on schedule check
