[2024-01-08T05:06:24.885+0000] {taskinstance.py:1957} INFO - Dependencies all met for dep_context=non-requeueable deps ti=<TaskInstance: etl_to_datalake.table_source_a scheduled__2024-01-07T00:00:00+00:00 [queued]>
[2024-01-08T05:06:24.899+0000] {taskinstance.py:1957} INFO - Dependencies all met for dep_context=requeueable deps ti=<TaskInstance: etl_to_datalake.table_source_a scheduled__2024-01-07T00:00:00+00:00 [queued]>
[2024-01-08T05:06:24.900+0000] {taskinstance.py:2171} INFO - Starting attempt 3 of 5
[2024-01-08T05:06:24.923+0000] {taskinstance.py:2192} INFO - Executing <Task(PythonOperator): table_source_a> on 2024-01-07 00:00:00+00:00
[2024-01-08T05:06:24.936+0000] {standard_task_runner.py:60} INFO - Started process 280 to run task
[2024-01-08T05:06:24.944+0000] {standard_task_runner.py:87} INFO - Running: ['***', 'tasks', 'run', 'etl_to_datalake', 'table_source_a', 'scheduled__2024-01-07T00:00:00+00:00', '--job-id', '31', '--raw', '--subdir', 'DAGS_FOLDER/etl_to_datalake.py', '--cfg-path', '/tmp/tmp5xmlnre0']
[2024-01-08T05:06:24.947+0000] {standard_task_runner.py:88} INFO - Job 31: Subtask table_source_a
[2024-01-08T05:06:25.049+0000] {task_command.py:423} INFO - Running <TaskInstance: etl_to_datalake.table_source_a scheduled__2024-01-07T00:00:00+00:00 [running]> on host 6d1c1d696e23
[2024-01-08T05:06:25.185+0000] {taskinstance.py:2481} INFO - Exporting env vars: AIRFLOW_CTX_DAG_OWNER='***' AIRFLOW_CTX_DAG_ID='etl_to_datalake' AIRFLOW_CTX_TASK_ID='table_source_a' AIRFLOW_CTX_EXECUTION_DATE='2024-01-07T00:00:00+00:00' AIRFLOW_CTX_TRY_NUMBER='3' AIRFLOW_CTX_DAG_RUN_ID='scheduled__2024-01-07T00:00:00+00:00'
[2024-01-08T05:06:25.204+0000] {connection.py:234} WARNING - Connection schemes (type: google_cloud_platform) shall not contain '_' according to RFC3986.
[2024-01-08T05:06:25.278+0000] {logging_mixin.py:188} INFO - successfully created BQ client
[2024-01-08T05:06:26.195+0000] {taskinstance.py:2699} ERROR - Task failed with exception
Traceback (most recent call last):
  File "/home/airflow/.local/lib/python3.8/site-packages/airflow/models/taskinstance.py", line 433, in _execute_task
    result = execute_callable(context=context, **execute_callable_kwargs)
  File "/home/airflow/.local/lib/python3.8/site-packages/airflow/operators/python.py", line 199, in execute
    return_value = self.execute_callable()
  File "/home/airflow/.local/lib/python3.8/site-packages/airflow/operators/python.py", line 216, in execute_callable
    return self.python_callable(*self.op_args, **self.op_kwargs)
  File "/opt/airflow/dags/etl_to_datalake.py", line 60, in load_query_result_to_bq
    raise e
  File "/opt/airflow/dags/etl_to_datalake.py", line 57, in load_query_result_to_bq
    query_job_res = query_job.result()
  File "/home/airflow/.local/lib/python3.8/site-packages/google/cloud/bigquery/job/query.py", line 1595, in result
    do_get_result()
  File "/home/airflow/.local/lib/python3.8/site-packages/google/api_core/retry.py", line 372, in retry_wrapped_func
    return retry_target(
  File "/home/airflow/.local/lib/python3.8/site-packages/google/api_core/retry.py", line 207, in retry_target
    result = target()
  File "/home/airflow/.local/lib/python3.8/site-packages/google/cloud/bigquery/job/query.py", line 1584, in do_get_result
    super(QueryJob, self).result(retry=retry, timeout=timeout)
  File "/home/airflow/.local/lib/python3.8/site-packages/google/cloud/bigquery/job/base.py", line 952, in result
    return super(_AsyncJob, self).result(timeout=timeout, **kwargs)
  File "/home/airflow/.local/lib/python3.8/site-packages/google/api_core/future/polling.py", line 261, in result
    raise self._exception
google.api_core.exceptions.NotFound: 404 Not found: Dataset alpine-life-350508:project_x_datalake was not found in location US

Location: US
Job ID: b22516ae-672d-48cc-bb3f-6344f45eebf8

[2024-01-08T05:06:26.213+0000] {taskinstance.py:1138} INFO - Marking task as UP_FOR_RETRY. dag_id=etl_to_datalake, task_id=table_source_a, execution_date=20240107T000000, start_date=20240108T050624, end_date=20240108T050626
[2024-01-08T05:06:26.236+0000] {standard_task_runner.py:107} ERROR - Failed to execute job 31 for task table_source_a (404 Not found: Dataset alpine-life-350508:project_x_datalake was not found in location US

Location: US
Job ID: b22516ae-672d-48cc-bb3f-6344f45eebf8
; 280)
[2024-01-08T05:06:26.289+0000] {local_task_job_runner.py:234} INFO - Task exited with return code 1
[2024-01-08T05:06:26.323+0000] {taskinstance.py:3281} INFO - 0 downstream tasks scheduled from follow-on schedule check
