[2024-01-08T05:11:29.091+0000] {scheduler_job_runner.py:781} ERROR - Executor reports task instance <TaskInstance: etl_to_datalake.table_source_a scheduled__2024-01-07T00:00:00+00:00 [queued]> finished (failed) although the task says it's queued. (Info: None) Was the task killed externally?
