[2024-01-13T12:08:23.563+0000] {taskinstance.py:1957} INFO - Dependencies all met for dep_context=non-requeueable deps ti=<TaskInstance: etl_to_datalake.table_source_b scheduled__2024-01-10T00:00:00+00:00 [queued]>
[2024-01-13T12:08:23.606+0000] {taskinstance.py:1957} INFO - Dependencies all met for dep_context=requeueable deps ti=<TaskInstance: etl_to_datalake.table_source_b scheduled__2024-01-10T00:00:00+00:00 [queued]>
[2024-01-13T12:08:23.609+0000] {taskinstance.py:2171} INFO - Starting attempt 1 of 3
[2024-01-13T12:08:23.645+0000] {taskinstance.py:2192} INFO - Executing <Task(PythonOperator): table_source_b> on 2024-01-10 00:00:00+00:00
[2024-01-13T12:08:23.663+0000] {standard_task_runner.py:60} INFO - Started process 97 to run task
[2024-01-13T12:08:23.679+0000] {standard_task_runner.py:87} INFO - Running: ['***', 'tasks', 'run', 'etl_to_datalake', 'table_source_b', 'scheduled__2024-01-10T00:00:00+00:00', '--job-id', '32', '--raw', '--subdir', 'DAGS_FOLDER/etl_to_datalake.py', '--cfg-path', '/tmp/tmpcmftf2m8']
[2024-01-13T12:08:23.689+0000] {standard_task_runner.py:88} INFO - Job 32: Subtask table_source_b
[2024-01-13T12:08:23.887+0000] {task_command.py:423} INFO - Running <TaskInstance: etl_to_datalake.table_source_b scheduled__2024-01-10T00:00:00+00:00 [running]> on host cc6de2d520c9
[2024-01-13T12:08:24.132+0000] {taskinstance.py:2481} INFO - Exporting env vars: AIRFLOW_CTX_DAG_OWNER='***' AIRFLOW_CTX_DAG_ID='etl_to_datalake' AIRFLOW_CTX_TASK_ID='table_source_b' AIRFLOW_CTX_EXECUTION_DATE='2024-01-10T00:00:00+00:00' AIRFLOW_CTX_TRY_NUMBER='1' AIRFLOW_CTX_DAG_RUN_ID='scheduled__2024-01-10T00:00:00+00:00'
[2024-01-13T12:08:24.284+0000] {taskinstance.py:2699} ERROR - Task failed with exception
Traceback (most recent call last):
  File "/home/airflow/.local/lib/python3.8/site-packages/airflow/models/taskinstance.py", line 433, in _execute_task
    result = execute_callable(context=context, **execute_callable_kwargs)
  File "/home/airflow/.local/lib/python3.8/site-packages/airflow/operators/python.py", line 199, in execute
    return_value = self.execute_callable()
  File "/home/airflow/.local/lib/python3.8/site-packages/airflow/operators/python.py", line 216, in execute_callable
    return self.python_callable(*self.op_args, **self.op_kwargs)
  File "/opt/airflow/dags/etl_to_datalake.py", line 80, in process_datalake
    load_query_result_to_bq(dict_config["sql"], dict_config["write_disposition"],
  File "/opt/airflow/dags/etl_to_datalake.py", line 60, in load_query_result_to_bq
    raise e
  File "/opt/airflow/dags/etl_to_datalake.py", line 46, in load_query_result_to_bq
    bq_client = init_bq_client()
  File "/opt/airflow/dags/etl_to_datalake.py", line 35, in init_bq_client
    raise e
  File "/opt/airflow/dags/etl_to_datalake.py", line 24, in init_bq_client
    conn = Connection.get_connection_from_secrets(conn_id='dwh-creds')
  File "/home/airflow/.local/lib/python3.8/site-packages/airflow/models/connection.py", line 479, in get_connection_from_secrets
    raise AirflowNotFoundException(f"The conn_id `{conn_id}` isn't defined")
airflow.exceptions.AirflowNotFoundException: The conn_id `dwh-creds` isn't defined
[2024-01-13T12:08:24.301+0000] {taskinstance.py:1138} INFO - Marking task as UP_FOR_RETRY. dag_id=etl_to_datalake, task_id=table_source_b, execution_date=20240110T000000, start_date=20240113T120823, end_date=20240113T120824
[2024-01-13T12:08:24.342+0000] {standard_task_runner.py:107} ERROR - Failed to execute job 32 for task table_source_b (The conn_id `dwh-creds` isn't defined; 97)
[2024-01-13T12:08:24.395+0000] {local_task_job_runner.py:234} INFO - Task exited with return code 1
[2024-01-13T12:08:24.434+0000] {taskinstance.py:3281} INFO - 0 downstream tasks scheduled from follow-on schedule check
