[2024-01-08T04:40:13.728+0000] {taskinstance.py:1957} INFO - Dependencies all met for dep_context=non-requeueable deps ti=<TaskInstance: etl_to_dwh.fact_a scheduled__2024-01-07T00:00:00+00:00 [queued]>
[2024-01-08T04:40:13.851+0000] {taskinstance.py:1957} INFO - Dependencies all met for dep_context=requeueable deps ti=<TaskInstance: etl_to_dwh.fact_a scheduled__2024-01-07T00:00:00+00:00 [queued]>
[2024-01-08T04:40:13.851+0000] {taskinstance.py:2171} INFO - Starting attempt 1 of 3
[2024-01-08T04:40:13.976+0000] {taskinstance.py:2192} INFO - Executing <Task(PythonOperator): fact_a> on 2024-01-07 00:00:00+00:00
[2024-01-08T04:40:14.089+0000] {standard_task_runner.py:60} INFO - Started process 1179 to run task
[2024-01-08T04:40:14.123+0000] {standard_task_runner.py:87} INFO - Running: ['***', 'tasks', 'run', 'etl_to_dwh', 'fact_a', 'scheduled__2024-01-07T00:00:00+00:00', '--job-id', '16', '--raw', '--subdir', 'DAGS_FOLDER/etl_to_dwh.py', '--cfg-path', '/tmp/tmpyqoel1vz']
[2024-01-08T04:40:14.145+0000] {standard_task_runner.py:88} INFO - Job 16: Subtask fact_a
[2024-01-08T04:40:14.427+0000] {task_command.py:423} INFO - Running <TaskInstance: etl_to_dwh.fact_a scheduled__2024-01-07T00:00:00+00:00 [running]> on host 6d1c1d696e23
[2024-01-08T04:40:15.062+0000] {taskinstance.py:2481} INFO - Exporting env vars: AIRFLOW_CTX_DAG_OWNER='***' AIRFLOW_CTX_DAG_ID='etl_to_dwh' AIRFLOW_CTX_TASK_ID='fact_a' AIRFLOW_CTX_EXECUTION_DATE='2024-01-07T00:00:00+00:00' AIRFLOW_CTX_TRY_NUMBER='1' AIRFLOW_CTX_DAG_RUN_ID='scheduled__2024-01-07T00:00:00+00:00'
[2024-01-08T04:40:15.271+0000] {taskinstance.py:2699} ERROR - Task failed with exception
Traceback (most recent call last):
  File "/home/airflow/.local/lib/python3.8/site-packages/airflow/models/taskinstance.py", line 433, in _execute_task
    result = execute_callable(context=context, **execute_callable_kwargs)
  File "/home/airflow/.local/lib/python3.8/site-packages/airflow/operators/python.py", line 199, in execute
    return_value = self.execute_callable()
  File "/home/airflow/.local/lib/python3.8/site-packages/airflow/operators/python.py", line 216, in execute_callable
    return self.python_callable(*self.op_args, **self.op_kwargs)
  File "/opt/airflow/dags/etl_to_dwh.py", line 80, in process_dwh
    load_query_result_to_bq(dict_config["sql"], dict_config["write_disposition"],
  File "/opt/airflow/dags/etl_to_dwh.py", line 60, in load_query_result_to_bq
    raise e
  File "/opt/airflow/dags/etl_to_dwh.py", line 46, in load_query_result_to_bq
    bq_client = init_bq_client()
  File "/opt/airflow/dags/etl_to_dwh.py", line 35, in init_bq_client
    raise e
  File "/opt/airflow/dags/etl_to_dwh.py", line 24, in init_bq_client
    conn = Connection.get_connection_from_secrets(conn_id='dwh-creds')
  File "/home/airflow/.local/lib/python3.8/site-packages/airflow/models/connection.py", line 479, in get_connection_from_secrets
    raise AirflowNotFoundException(f"The conn_id `{conn_id}` isn't defined")
airflow.exceptions.AirflowNotFoundException: The conn_id `dwh-creds` isn't defined
[2024-01-08T04:40:15.278+0000] {taskinstance.py:1138} INFO - Marking task as UP_FOR_RETRY. dag_id=etl_to_dwh, task_id=fact_a, execution_date=20240107T000000, start_date=20240108T044013, end_date=20240108T044015
[2024-01-08T04:40:15.327+0000] {standard_task_runner.py:107} ERROR - Failed to execute job 16 for task fact_a (The conn_id `dwh-creds` isn't defined; 1179)
[2024-01-08T04:40:15.403+0000] {local_task_job_runner.py:234} INFO - Task exited with return code 1
[2024-01-08T04:40:15.469+0000] {taskinstance.py:3281} INFO - 0 downstream tasks scheduled from follow-on schedule check
[2024-01-08T04:54:17.064+0000] {taskinstance.py:1957} INFO - Dependencies all met for dep_context=non-requeueable deps ti=<TaskInstance: etl_to_dwh.fact_a scheduled__2024-01-07T00:00:00+00:00 [queued]>
[2024-01-08T04:54:17.087+0000] {taskinstance.py:1957} INFO - Dependencies all met for dep_context=requeueable deps ti=<TaskInstance: etl_to_dwh.fact_a scheduled__2024-01-07T00:00:00+00:00 [queued]>
[2024-01-08T04:54:17.087+0000] {taskinstance.py:2171} INFO - Starting attempt 1 of 3
[2024-01-08T04:54:17.101+0000] {taskinstance.py:2192} INFO - Executing <Task(PythonOperator): fact_a> on 2024-01-07 00:00:00+00:00
[2024-01-08T04:54:17.109+0000] {standard_task_runner.py:60} INFO - Started process 74 to run task
[2024-01-08T04:54:17.114+0000] {standard_task_runner.py:87} INFO - Running: ['***', 'tasks', 'run', 'etl_to_dwh', 'fact_a', 'scheduled__2024-01-07T00:00:00+00:00', '--job-id', '22', '--raw', '--subdir', 'DAGS_FOLDER/etl_to_dwh.py', '--cfg-path', '/tmp/tmpcx4ulpcb']
[2024-01-08T04:54:17.116+0000] {standard_task_runner.py:88} INFO - Job 22: Subtask fact_a
[2024-01-08T04:54:17.176+0000] {task_command.py:423} INFO - Running <TaskInstance: etl_to_dwh.fact_a scheduled__2024-01-07T00:00:00+00:00 [running]> on host 6d1c1d696e23
[2024-01-08T04:54:17.266+0000] {taskinstance.py:2481} INFO - Exporting env vars: AIRFLOW_CTX_DAG_OWNER='***' AIRFLOW_CTX_DAG_ID='etl_to_dwh' AIRFLOW_CTX_TASK_ID='fact_a' AIRFLOW_CTX_EXECUTION_DATE='2024-01-07T00:00:00+00:00' AIRFLOW_CTX_TRY_NUMBER='1' AIRFLOW_CTX_DAG_RUN_ID='scheduled__2024-01-07T00:00:00+00:00'
[2024-01-08T04:54:17.303+0000] {taskinstance.py:2699} ERROR - Task failed with exception
Traceback (most recent call last):
  File "/home/airflow/.local/lib/python3.8/site-packages/airflow/models/taskinstance.py", line 433, in _execute_task
    result = execute_callable(context=context, **execute_callable_kwargs)
  File "/home/airflow/.local/lib/python3.8/site-packages/airflow/operators/python.py", line 199, in execute
    return_value = self.execute_callable()
  File "/home/airflow/.local/lib/python3.8/site-packages/airflow/operators/python.py", line 216, in execute_callable
    return self.python_callable(*self.op_args, **self.op_kwargs)
  File "/opt/airflow/dags/etl_to_dwh.py", line 80, in process_dwh
    load_query_result_to_bq(dict_config["sql"], dict_config["write_disposition"],
  File "/opt/airflow/dags/etl_to_dwh.py", line 60, in load_query_result_to_bq
    raise e
  File "/opt/airflow/dags/etl_to_dwh.py", line 46, in load_query_result_to_bq
    bq_client = init_bq_client()
  File "/opt/airflow/dags/etl_to_dwh.py", line 35, in init_bq_client
    raise e
  File "/opt/airflow/dags/etl_to_dwh.py", line 24, in init_bq_client
    conn = Connection.get_connection_from_secrets(conn_id='dwh-creds')
  File "/home/airflow/.local/lib/python3.8/site-packages/airflow/models/connection.py", line 479, in get_connection_from_secrets
    raise AirflowNotFoundException(f"The conn_id `{conn_id}` isn't defined")
airflow.exceptions.AirflowNotFoundException: The conn_id `dwh-creds` isn't defined
[2024-01-08T04:54:17.307+0000] {taskinstance.py:1138} INFO - Marking task as UP_FOR_RETRY. dag_id=etl_to_dwh, task_id=fact_a, execution_date=20240107T000000, start_date=20240108T045417, end_date=20240108T045417
[2024-01-08T04:54:17.320+0000] {standard_task_runner.py:107} ERROR - Failed to execute job 22 for task fact_a (The conn_id `dwh-creds` isn't defined; 74)
[2024-01-08T04:54:17.366+0000] {local_task_job_runner.py:234} INFO - Task exited with return code 1
[2024-01-08T04:54:17.387+0000] {taskinstance.py:3281} INFO - 0 downstream tasks scheduled from follow-on schedule check
