[2024-01-08T04:59:26.277+0000] {taskinstance.py:1957} INFO - Dependencies all met for dep_context=non-requeueable deps ti=<TaskInstance: etl_to_dwh.fact_a scheduled__2024-01-07T00:00:00+00:00 [queued]>
[2024-01-08T04:59:26.287+0000] {taskinstance.py:1957} INFO - Dependencies all met for dep_context=requeueable deps ti=<TaskInstance: etl_to_dwh.fact_a scheduled__2024-01-07T00:00:00+00:00 [queued]>
[2024-01-08T04:59:26.288+0000] {taskinstance.py:2171} INFO - Starting attempt 3 of 5
[2024-01-08T04:59:26.304+0000] {taskinstance.py:2192} INFO - Executing <Task(PythonOperator): fact_a> on 2024-01-07 00:00:00+00:00
[2024-01-08T04:59:26.313+0000] {standard_task_runner.py:60} INFO - Started process 153 to run task
[2024-01-08T04:59:26.319+0000] {standard_task_runner.py:87} INFO - Running: ['***', 'tasks', 'run', 'etl_to_dwh', 'fact_a', 'scheduled__2024-01-07T00:00:00+00:00', '--job-id', '24', '--raw', '--subdir', 'DAGS_FOLDER/etl_to_dwh.py', '--cfg-path', '/tmp/tmpt1_wqa3i']
[2024-01-08T04:59:26.321+0000] {standard_task_runner.py:88} INFO - Job 24: Subtask fact_a
[2024-01-08T04:59:26.385+0000] {task_command.py:423} INFO - Running <TaskInstance: etl_to_dwh.fact_a scheduled__2024-01-07T00:00:00+00:00 [running]> on host 6d1c1d696e23
[2024-01-08T04:59:26.479+0000] {taskinstance.py:2481} INFO - Exporting env vars: AIRFLOW_CTX_DAG_OWNER='***' AIRFLOW_CTX_DAG_ID='etl_to_dwh' AIRFLOW_CTX_TASK_ID='fact_a' AIRFLOW_CTX_EXECUTION_DATE='2024-01-07T00:00:00+00:00' AIRFLOW_CTX_TRY_NUMBER='3' AIRFLOW_CTX_DAG_RUN_ID='scheduled__2024-01-07T00:00:00+00:00'
[2024-01-08T04:59:26.507+0000] {connection.py:234} WARNING - Connection schemes (type: google_cloud_platform) shall not contain '_' according to RFC3986.
[2024-01-08T04:59:26.565+0000] {logging_mixin.py:188} INFO - successfully created BQ client
[2024-01-08T04:59:27.170+0000] {taskinstance.py:2699} ERROR - Task failed with exception
Traceback (most recent call last):
  File "/home/airflow/.local/lib/python3.8/site-packages/airflow/models/taskinstance.py", line 433, in _execute_task
    result = execute_callable(context=context, **execute_callable_kwargs)
  File "/home/airflow/.local/lib/python3.8/site-packages/airflow/operators/python.py", line 199, in execute
    return_value = self.execute_callable()
  File "/home/airflow/.local/lib/python3.8/site-packages/airflow/operators/python.py", line 216, in execute_callable
    return self.python_callable(*self.op_args, **self.op_kwargs)
  File "/opt/airflow/dags/etl_to_dwh.py", line 80, in process_dwh
    load_query_result_to_bq(dict_config["sql"], dict_config["write_disposition"],
  File "/opt/airflow/dags/etl_to_dwh.py", line 60, in load_query_result_to_bq
    raise e
  File "/opt/airflow/dags/etl_to_dwh.py", line 57, in load_query_result_to_bq
    query_job_res = query_job.result()
  File "/home/airflow/.local/lib/python3.8/site-packages/google/cloud/bigquery/job/query.py", line 1595, in result
    do_get_result()
  File "/home/airflow/.local/lib/python3.8/site-packages/google/api_core/retry.py", line 372, in retry_wrapped_func
    return retry_target(
  File "/home/airflow/.local/lib/python3.8/site-packages/google/api_core/retry.py", line 207, in retry_target
    result = target()
  File "/home/airflow/.local/lib/python3.8/site-packages/google/cloud/bigquery/job/query.py", line 1584, in do_get_result
    super(QueryJob, self).result(retry=retry, timeout=timeout)
  File "/home/airflow/.local/lib/python3.8/site-packages/google/cloud/bigquery/job/base.py", line 952, in result
    return super(_AsyncJob, self).result(timeout=timeout, **kwargs)
  File "/home/airflow/.local/lib/python3.8/site-packages/google/api_core/future/polling.py", line 261, in result
    raise self._exception
google.api_core.exceptions.NotFound: 404 Not found: Dataset deft-beacon-358408:project_x_dwh was not found in location US

Location: US
Job ID: 9657ac3d-b4b5-47fd-a769-30ec470730d3

[2024-01-08T04:59:27.183+0000] {taskinstance.py:1138} INFO - Marking task as UP_FOR_RETRY. dag_id=etl_to_dwh, task_id=fact_a, execution_date=20240107T000000, start_date=20240108T045926, end_date=20240108T045927
[2024-01-08T04:59:27.198+0000] {standard_task_runner.py:107} ERROR - Failed to execute job 24 for task fact_a (404 Not found: Dataset deft-beacon-358408:project_x_dwh was not found in location US

Location: US
Job ID: 9657ac3d-b4b5-47fd-a769-30ec470730d3
; 153)
[2024-01-08T04:59:27.215+0000] {local_task_job_runner.py:234} INFO - Task exited with return code 1
[2024-01-08T04:59:27.235+0000] {taskinstance.py:3281} INFO - 0 downstream tasks scheduled from follow-on schedule check
