[2024-01-08T05:10:18.483+0000] {taskinstance.py:1957} INFO - Dependencies all met for dep_context=non-requeueable deps ti=<TaskInstance: etl_to_datalake.table_source_b scheduled__2024-01-07T00:00:00+00:00 [queued]>
[2024-01-08T05:10:18.494+0000] {taskinstance.py:1957} INFO - Dependencies all met for dep_context=requeueable deps ti=<TaskInstance: etl_to_datalake.table_source_b scheduled__2024-01-07T00:00:00+00:00 [queued]>
[2024-01-08T05:10:18.494+0000] {taskinstance.py:2171} INFO - Starting attempt 1 of 3
[2024-01-08T05:10:18.511+0000] {taskinstance.py:2192} INFO - Executing <Task(PythonOperator): table_source_b> on 2024-01-07 00:00:00+00:00
[2024-01-08T05:10:18.519+0000] {standard_task_runner.py:60} INFO - Started process 342 to run task
[2024-01-08T05:10:18.525+0000] {standard_task_runner.py:87} INFO - Running: ['***', 'tasks', 'run', 'etl_to_datalake', 'table_source_b', 'scheduled__2024-01-07T00:00:00+00:00', '--job-id', '33', '--raw', '--subdir', 'DAGS_FOLDER/etl_to_dwh.py', '--cfg-path', '/tmp/tmp37n13az4']
[2024-01-08T05:10:18.527+0000] {standard_task_runner.py:88} INFO - Job 33: Subtask table_source_b
[2024-01-08T05:10:18.596+0000] {task_command.py:423} INFO - Running <TaskInstance: etl_to_datalake.table_source_b scheduled__2024-01-07T00:00:00+00:00 [running]> on host 6d1c1d696e23
[2024-01-08T05:10:18.691+0000] {taskinstance.py:2481} INFO - Exporting env vars: AIRFLOW_CTX_DAG_OWNER='***' AIRFLOW_CTX_DAG_ID='etl_to_datalake' AIRFLOW_CTX_TASK_ID='table_source_b' AIRFLOW_CTX_EXECUTION_DATE='2024-01-07T00:00:00+00:00' AIRFLOW_CTX_TRY_NUMBER='1' AIRFLOW_CTX_DAG_RUN_ID='scheduled__2024-01-07T00:00:00+00:00'
[2024-01-08T05:10:18.737+0000] {taskinstance.py:2699} ERROR - Task failed with exception
Traceback (most recent call last):
  File "/home/airflow/.local/lib/python3.8/site-packages/airflow/models/taskinstance.py", line 433, in _execute_task
    result = execute_callable(context=context, **execute_callable_kwargs)
  File "/home/airflow/.local/lib/python3.8/site-packages/airflow/operators/python.py", line 199, in execute
    return_value = self.execute_callable()
  File "/home/airflow/.local/lib/python3.8/site-packages/airflow/operators/python.py", line 216, in execute_callable
    return self.python_callable(*self.op_args, **self.op_kwargs)
  File "/opt/airflow/dags/etl_to_dwh.py", line 80, in process_datalake
    load_query_result_to_bq(dict_config["sql"], dict_config["write_disposition"],
  File "/opt/airflow/dags/etl_to_dwh.py", line 60, in load_query_result_to_bq
    raise e
  File "/opt/airflow/dags/etl_to_dwh.py", line 46, in load_query_result_to_bq
    bq_client = init_bq_client()
  File "/opt/airflow/dags/etl_to_dwh.py", line 35, in init_bq_client
    raise e
  File "/opt/airflow/dags/etl_to_dwh.py", line 24, in init_bq_client
    conn = Connection.get_connection_from_secrets(conn_id='datalake-creds')
  File "/home/airflow/.local/lib/python3.8/site-packages/airflow/models/connection.py", line 479, in get_connection_from_secrets
    raise AirflowNotFoundException(f"The conn_id `{conn_id}` isn't defined")
airflow.exceptions.AirflowNotFoundException: The conn_id `datalake-creds` isn't defined
[2024-01-08T05:10:18.742+0000] {taskinstance.py:1138} INFO - Marking task as UP_FOR_RETRY. dag_id=etl_to_datalake, task_id=table_source_b, execution_date=20240107T000000, start_date=20240108T051018, end_date=20240108T051018
[2024-01-08T05:10:18.754+0000] {standard_task_runner.py:107} ERROR - Failed to execute job 33 for task table_source_b (The conn_id `datalake-creds` isn't defined; 342)
[2024-01-08T05:10:18.780+0000] {local_task_job_runner.py:234} INFO - Task exited with return code 1
[2024-01-08T05:10:18.801+0000] {taskinstance.py:3281} INFO - 0 downstream tasks scheduled from follow-on schedule check
[2024-01-08T07:21:02.014+0000] {taskinstance.py:1957} INFO - Dependencies all met for dep_context=non-requeueable deps ti=<TaskInstance: etl_to_datalake.table_source_b scheduled__2024-01-07T00:00:00+00:00 [queued]>
[2024-01-08T07:21:02.035+0000] {taskinstance.py:1957} INFO - Dependencies all met for dep_context=requeueable deps ti=<TaskInstance: etl_to_datalake.table_source_b scheduled__2024-01-07T00:00:00+00:00 [queued]>
[2024-01-08T07:21:02.036+0000] {taskinstance.py:2171} INFO - Starting attempt 1 of 3
[2024-01-08T07:21:02.056+0000] {taskinstance.py:2192} INFO - Executing <Task(PythonOperator): table_source_b> on 2024-01-07 00:00:00+00:00
[2024-01-08T07:21:02.065+0000] {standard_task_runner.py:60} INFO - Started process 145 to run task
[2024-01-08T07:21:02.073+0000] {standard_task_runner.py:87} INFO - Running: ['***', 'tasks', 'run', 'etl_to_datalake', 'table_source_b', 'scheduled__2024-01-07T00:00:00+00:00', '--job-id', '54', '--raw', '--subdir', 'DAGS_FOLDER/etl_to_datalake.py', '--cfg-path', '/tmp/tmp4phnozpg']
[2024-01-08T07:21:02.076+0000] {standard_task_runner.py:88} INFO - Job 54: Subtask table_source_b
[2024-01-08T07:21:02.166+0000] {task_command.py:423} INFO - Running <TaskInstance: etl_to_datalake.table_source_b scheduled__2024-01-07T00:00:00+00:00 [running]> on host 6d1c1d696e23
[2024-01-08T07:21:02.276+0000] {taskinstance.py:2481} INFO - Exporting env vars: AIRFLOW_CTX_DAG_OWNER='***' AIRFLOW_CTX_DAG_ID='etl_to_datalake' AIRFLOW_CTX_TASK_ID='table_source_b' AIRFLOW_CTX_EXECUTION_DATE='2024-01-07T00:00:00+00:00' AIRFLOW_CTX_TRY_NUMBER='1' AIRFLOW_CTX_DAG_RUN_ID='scheduled__2024-01-07T00:00:00+00:00'
[2024-01-08T07:21:02.323+0000] {connection.py:234} WARNING - Connection schemes (type: google_cloud_platform) shall not contain '_' according to RFC3986.
[2024-01-08T07:21:02.391+0000] {logging_mixin.py:188} INFO - successfully created BQ client
[2024-01-08T07:21:05.409+0000] {logging_mixin.py:188} INFO - successfully load data to alpine-life-350508.project_x_datalake.table_source_b
[2024-01-08T07:21:05.409+0000] {python.py:201} INFO - Done. Returned value was: None
[2024-01-08T07:21:05.427+0000] {taskinstance.py:1138} INFO - Marking task as SUCCESS. dag_id=etl_to_datalake, task_id=table_source_b, execution_date=20240107T000000, start_date=20240108T072102, end_date=20240108T072105
[2024-01-08T07:21:05.500+0000] {local_task_job_runner.py:234} INFO - Task exited with return code 0
[2024-01-08T07:21:05.529+0000] {taskinstance.py:3281} INFO - 0 downstream tasks scheduled from follow-on schedule check
[2024-01-08T07:29:47.691+0000] {taskinstance.py:1957} INFO - Dependencies all met for dep_context=non-requeueable deps ti=<TaskInstance: etl_to_datalake.table_source_b scheduled__2024-01-07T00:00:00+00:00 [queued]>
[2024-01-08T07:29:47.804+0000] {taskinstance.py:1957} INFO - Dependencies all met for dep_context=requeueable deps ti=<TaskInstance: etl_to_datalake.table_source_b scheduled__2024-01-07T00:00:00+00:00 [queued]>
[2024-01-08T07:29:47.815+0000] {taskinstance.py:2171} INFO - Starting attempt 1 of 3
[2024-01-08T07:29:47.872+0000] {taskinstance.py:2192} INFO - Executing <Task(PythonOperator): table_source_b> on 2024-01-07 00:00:00+00:00
[2024-01-08T07:29:47.924+0000] {standard_task_runner.py:60} INFO - Started process 337 to run task
[2024-01-08T07:29:47.937+0000] {standard_task_runner.py:87} INFO - Running: ['***', 'tasks', 'run', 'etl_to_datalake', 'table_source_b', 'scheduled__2024-01-07T00:00:00+00:00', '--job-id', '62', '--raw', '--subdir', 'DAGS_FOLDER/etl_to_datalake.py', '--cfg-path', '/tmp/tmp42_g60fc']
[2024-01-08T07:29:47.940+0000] {standard_task_runner.py:88} INFO - Job 62: Subtask table_source_b
[2024-01-08T07:29:48.174+0000] {task_command.py:423} INFO - Running <TaskInstance: etl_to_datalake.table_source_b scheduled__2024-01-07T00:00:00+00:00 [running]> on host 6d1c1d696e23
[2024-01-08T07:29:48.480+0000] {taskinstance.py:2481} INFO - Exporting env vars: AIRFLOW_CTX_DAG_OWNER='***' AIRFLOW_CTX_DAG_ID='etl_to_datalake' AIRFLOW_CTX_TASK_ID='table_source_b' AIRFLOW_CTX_EXECUTION_DATE='2024-01-07T00:00:00+00:00' AIRFLOW_CTX_TRY_NUMBER='1' AIRFLOW_CTX_DAG_RUN_ID='scheduled__2024-01-07T00:00:00+00:00'
[2024-01-08T07:29:48.568+0000] {connection.py:234} WARNING - Connection schemes (type: google_cloud_platform) shall not contain '_' according to RFC3986.
[2024-01-08T07:29:48.671+0000] {logging_mixin.py:188} INFO - successfully created BQ client
[2024-01-08T07:29:53.961+0000] {logging_mixin.py:188} INFO - successfully load data to alpine-life-350508.project_x_datalake.table_source_b
[2024-01-08T07:29:53.962+0000] {python.py:201} INFO - Done. Returned value was: None
[2024-01-08T07:29:53.975+0000] {taskinstance.py:1138} INFO - Marking task as SUCCESS. dag_id=etl_to_datalake, task_id=table_source_b, execution_date=20240107T000000, start_date=20240108T072947, end_date=20240108T072953
[2024-01-08T07:29:54.026+0000] {local_task_job_runner.py:234} INFO - Task exited with return code 0
[2024-01-08T07:29:54.048+0000] {taskinstance.py:3281} INFO - 0 downstream tasks scheduled from follow-on schedule check
[2024-01-13T12:08:19.499+0000] {taskinstance.py:1957} INFO - Dependencies all met for dep_context=non-requeueable deps ti=<TaskInstance: etl_to_datalake.table_source_b scheduled__2024-01-07T00:00:00+00:00 [queued]>
[2024-01-13T12:08:19.589+0000] {taskinstance.py:1957} INFO - Dependencies all met for dep_context=requeueable deps ti=<TaskInstance: etl_to_datalake.table_source_b scheduled__2024-01-07T00:00:00+00:00 [queued]>
[2024-01-13T12:08:19.590+0000] {taskinstance.py:2171} INFO - Starting attempt 1 of 3
[2024-01-13T12:08:19.796+0000] {taskinstance.py:2192} INFO - Executing <Task(PythonOperator): table_source_b> on 2024-01-07 00:00:00+00:00
[2024-01-13T12:08:19.991+0000] {standard_task_runner.py:60} INFO - Started process 92 to run task
[2024-01-13T12:08:20.048+0000] {standard_task_runner.py:87} INFO - Running: ['***', 'tasks', 'run', 'etl_to_datalake', 'table_source_b', 'scheduled__2024-01-07T00:00:00+00:00', '--job-id', '26', '--raw', '--subdir', 'DAGS_FOLDER/etl_to_datalake.py', '--cfg-path', '/tmp/tmpld5s0qrb']
[2024-01-13T12:08:20.076+0000] {standard_task_runner.py:88} INFO - Job 26: Subtask table_source_b
[2024-01-13T12:08:20.680+0000] {task_command.py:423} INFO - Running <TaskInstance: etl_to_datalake.table_source_b scheduled__2024-01-07T00:00:00+00:00 [running]> on host cc6de2d520c9
[2024-01-13T12:08:21.175+0000] {taskinstance.py:2481} INFO - Exporting env vars: AIRFLOW_CTX_DAG_OWNER='***' AIRFLOW_CTX_DAG_ID='etl_to_datalake' AIRFLOW_CTX_TASK_ID='table_source_b' AIRFLOW_CTX_EXECUTION_DATE='2024-01-07T00:00:00+00:00' AIRFLOW_CTX_TRY_NUMBER='1' AIRFLOW_CTX_DAG_RUN_ID='scheduled__2024-01-07T00:00:00+00:00'
[2024-01-13T12:08:21.630+0000] {taskinstance.py:2699} ERROR - Task failed with exception
Traceback (most recent call last):
  File "/home/airflow/.local/lib/python3.8/site-packages/airflow/models/taskinstance.py", line 433, in _execute_task
    result = execute_callable(context=context, **execute_callable_kwargs)
  File "/home/airflow/.local/lib/python3.8/site-packages/airflow/operators/python.py", line 199, in execute
    return_value = self.execute_callable()
  File "/home/airflow/.local/lib/python3.8/site-packages/airflow/operators/python.py", line 216, in execute_callable
    return self.python_callable(*self.op_args, **self.op_kwargs)
  File "/opt/airflow/dags/etl_to_datalake.py", line 80, in process_datalake
    load_query_result_to_bq(dict_config["sql"], dict_config["write_disposition"],
  File "/opt/airflow/dags/etl_to_datalake.py", line 60, in load_query_result_to_bq
    raise e
  File "/opt/airflow/dags/etl_to_datalake.py", line 46, in load_query_result_to_bq
    bq_client = init_bq_client()
  File "/opt/airflow/dags/etl_to_datalake.py", line 35, in init_bq_client
    raise e
  File "/opt/airflow/dags/etl_to_datalake.py", line 24, in init_bq_client
    conn = Connection.get_connection_from_secrets(conn_id='dwh-creds')
  File "/home/airflow/.local/lib/python3.8/site-packages/airflow/models/connection.py", line 479, in get_connection_from_secrets
    raise AirflowNotFoundException(f"The conn_id `{conn_id}` isn't defined")
airflow.exceptions.AirflowNotFoundException: The conn_id `dwh-creds` isn't defined
[2024-01-13T12:08:21.654+0000] {taskinstance.py:1138} INFO - Marking task as UP_FOR_RETRY. dag_id=etl_to_datalake, task_id=table_source_b, execution_date=20240107T000000, start_date=20240113T120819, end_date=20240113T120821
[2024-01-13T12:08:21.763+0000] {standard_task_runner.py:107} ERROR - Failed to execute job 26 for task table_source_b (The conn_id `dwh-creds` isn't defined; 92)
[2024-01-13T12:08:21.952+0000] {local_task_job_runner.py:234} INFO - Task exited with return code 1
[2024-01-13T12:08:22.123+0000] {taskinstance.py:3281} INFO - 0 downstream tasks scheduled from follow-on schedule check
