[2024-01-08T05:15:21.173+0000] {taskinstance.py:1957} INFO - Dependencies all met for dep_context=non-requeueable deps ti=<TaskInstance: etl_to_datalake.table_source_b scheduled__2024-01-07T00:00:00+00:00 [queued]>
[2024-01-08T05:15:21.183+0000] {taskinstance.py:1957} INFO - Dependencies all met for dep_context=requeueable deps ti=<TaskInstance: etl_to_datalake.table_source_b scheduled__2024-01-07T00:00:00+00:00 [queued]>
[2024-01-08T05:15:21.184+0000] {taskinstance.py:2171} INFO - Starting attempt 2 of 3
[2024-01-08T05:15:21.198+0000] {taskinstance.py:2192} INFO - Executing <Task(PythonOperator): table_source_b> on 2024-01-07 00:00:00+00:00
[2024-01-08T05:15:21.207+0000] {standard_task_runner.py:60} INFO - Started process 419 to run task
[2024-01-08T05:15:21.213+0000] {standard_task_runner.py:87} INFO - Running: ['***', 'tasks', 'run', 'etl_to_datalake', 'table_source_b', 'scheduled__2024-01-07T00:00:00+00:00', '--job-id', '34', '--raw', '--subdir', 'DAGS_FOLDER/etl_to_datalake.py', '--cfg-path', '/tmp/tmpu306_ehe']
[2024-01-08T05:15:21.215+0000] {standard_task_runner.py:88} INFO - Job 34: Subtask table_source_b
[2024-01-08T05:15:21.312+0000] {task_command.py:423} INFO - Running <TaskInstance: etl_to_datalake.table_source_b scheduled__2024-01-07T00:00:00+00:00 [running]> on host 6d1c1d696e23
[2024-01-08T05:15:21.409+0000] {taskinstance.py:2481} INFO - Exporting env vars: AIRFLOW_CTX_DAG_OWNER='***' AIRFLOW_CTX_DAG_ID='etl_to_datalake' AIRFLOW_CTX_TASK_ID='table_source_b' AIRFLOW_CTX_EXECUTION_DATE='2024-01-07T00:00:00+00:00' AIRFLOW_CTX_TRY_NUMBER='2' AIRFLOW_CTX_DAG_RUN_ID='scheduled__2024-01-07T00:00:00+00:00'
[2024-01-08T05:15:21.445+0000] {connection.py:234} WARNING - Connection schemes (type: google_cloud_platform) shall not contain '_' according to RFC3986.
[2024-01-08T05:15:21.504+0000] {logging_mixin.py:188} INFO - successfully created BQ client
[2024-01-08T05:15:24.516+0000] {logging_mixin.py:188} INFO - successfully load data to alpine-life-350508.project_x_datalake.table_source_b
[2024-01-08T05:15:24.517+0000] {python.py:201} INFO - Done. Returned value was: None
[2024-01-08T05:15:24.531+0000] {taskinstance.py:1138} INFO - Marking task as SUCCESS. dag_id=etl_to_datalake, task_id=table_source_b, execution_date=20240107T000000, start_date=20240108T051521, end_date=20240108T051524
[2024-01-08T05:15:24.562+0000] {local_task_job_runner.py:234} INFO - Task exited with return code 0
[2024-01-08T05:15:24.593+0000] {taskinstance.py:3281} INFO - 0 downstream tasks scheduled from follow-on schedule check
[2024-01-13T12:13:33.270+0000] {taskinstance.py:1957} INFO - Dependencies all met for dep_context=non-requeueable deps ti=<TaskInstance: etl_to_datalake.table_source_b scheduled__2024-01-07T00:00:00+00:00 [queued]>
[2024-01-13T12:13:33.334+0000] {taskinstance.py:1957} INFO - Dependencies all met for dep_context=requeueable deps ti=<TaskInstance: etl_to_datalake.table_source_b scheduled__2024-01-07T00:00:00+00:00 [queued]>
[2024-01-13T12:13:33.334+0000] {taskinstance.py:2171} INFO - Starting attempt 2 of 3
[2024-01-13T12:13:33.430+0000] {taskinstance.py:2192} INFO - Executing <Task(PythonOperator): table_source_b> on 2024-01-07 00:00:00+00:00
[2024-01-13T12:13:33.472+0000] {standard_task_runner.py:60} INFO - Started process 206 to run task
[2024-01-13T12:13:33.506+0000] {standard_task_runner.py:87} INFO - Running: ['***', 'tasks', 'run', 'etl_to_datalake', 'table_source_b', 'scheduled__2024-01-07T00:00:00+00:00', '--job-id', '40', '--raw', '--subdir', 'DAGS_FOLDER/etl_to_datalake.py', '--cfg-path', '/tmp/tmp7yeosxk9']
[2024-01-13T12:13:33.510+0000] {standard_task_runner.py:88} INFO - Job 40: Subtask table_source_b
[2024-01-13T12:13:33.864+0000] {task_command.py:423} INFO - Running <TaskInstance: etl_to_datalake.table_source_b scheduled__2024-01-07T00:00:00+00:00 [running]> on host cc6de2d520c9
[2024-01-13T12:13:34.571+0000] {taskinstance.py:2481} INFO - Exporting env vars: AIRFLOW_CTX_DAG_OWNER='***' AIRFLOW_CTX_DAG_ID='etl_to_datalake' AIRFLOW_CTX_TASK_ID='table_source_b' AIRFLOW_CTX_EXECUTION_DATE='2024-01-07T00:00:00+00:00' AIRFLOW_CTX_TRY_NUMBER='2' AIRFLOW_CTX_DAG_RUN_ID='scheduled__2024-01-07T00:00:00+00:00'
[2024-01-13T12:13:34.810+0000] {taskinstance.py:2699} ERROR - Task failed with exception
Traceback (most recent call last):
  File "/home/airflow/.local/lib/python3.8/site-packages/airflow/models/taskinstance.py", line 433, in _execute_task
    result = execute_callable(context=context, **execute_callable_kwargs)
  File "/home/airflow/.local/lib/python3.8/site-packages/airflow/operators/python.py", line 199, in execute
    return_value = self.execute_callable()
  File "/home/airflow/.local/lib/python3.8/site-packages/airflow/operators/python.py", line 216, in execute_callable
    return self.python_callable(*self.op_args, **self.op_kwargs)
  File "/opt/airflow/dags/etl_to_datalake.py", line 80, in process_datalake
    load_query_result_to_bq(dict_config["sql"], dict_config["write_disposition"],
  File "/opt/airflow/dags/etl_to_datalake.py", line 60, in load_query_result_to_bq
    raise e
  File "/opt/airflow/dags/etl_to_datalake.py", line 46, in load_query_result_to_bq
    bq_client = init_bq_client()
  File "/opt/airflow/dags/etl_to_datalake.py", line 35, in init_bq_client
    raise e
  File "/opt/airflow/dags/etl_to_datalake.py", line 24, in init_bq_client
    conn = Connection.get_connection_from_secrets(conn_id='dwh-creds')
  File "/home/airflow/.local/lib/python3.8/site-packages/airflow/models/connection.py", line 479, in get_connection_from_secrets
    raise AirflowNotFoundException(f"The conn_id `{conn_id}` isn't defined")
airflow.exceptions.AirflowNotFoundException: The conn_id `dwh-creds` isn't defined
[2024-01-13T12:13:34.865+0000] {taskinstance.py:1138} INFO - Marking task as UP_FOR_RETRY. dag_id=etl_to_datalake, task_id=table_source_b, execution_date=20240107T000000, start_date=20240113T121333, end_date=20240113T121334
[2024-01-13T12:13:34.980+0000] {standard_task_runner.py:107} ERROR - Failed to execute job 40 for task table_source_b (The conn_id `dwh-creds` isn't defined; 206)
[2024-01-13T12:13:35.192+0000] {local_task_job_runner.py:234} INFO - Task exited with return code 1
[2024-01-13T12:13:35.272+0000] {taskinstance.py:3281} INFO - 0 downstream tasks scheduled from follow-on schedule check
