[2023-12-28T08:12:31.661+0000] {taskinstance.py:1957} INFO - Dependencies all met for dep_context=non-requeueable deps ti=<TaskInstance: etl_to_datalake.process_datalake scheduled__2022-11-12T00:00:00+00:00 [queued]>
[2023-12-28T08:12:31.800+0000] {taskinstance.py:1957} INFO - Dependencies all met for dep_context=requeueable deps ti=<TaskInstance: etl_to_datalake.process_datalake scheduled__2022-11-12T00:00:00+00:00 [queued]>
[2023-12-28T08:12:32.205+0000] {taskinstance.py:2171} INFO - Starting attempt 1 of 3
[2023-12-28T08:12:32.738+0000] {taskinstance.py:2192} INFO - Executing <Task(PythonOperator): process_datalake> on 2022-11-12 00:00:00+00:00
[2023-12-28T08:12:32.873+0000] {standard_task_runner.py:60} INFO - Started process 93 to run task
[2023-12-28T08:12:32.971+0000] {standard_task_runner.py:87} INFO - Running: ['***', 'tasks', 'run', 'etl_to_datalake', 'process_datalake', 'scheduled__2022-11-12T00:00:00+00:00', '--job-id', '11', '--raw', '--subdir', 'DAGS_FOLDER/etl_to_datalake.py', '--cfg-path', '/tmp/tmp9__l4rsw']
[2023-12-28T08:12:32.988+0000] {standard_task_runner.py:88} INFO - Job 11: Subtask process_datalake
[2023-12-28T08:12:34.248+0000] {task_command.py:423} INFO - Running <TaskInstance: etl_to_datalake.process_datalake scheduled__2022-11-12T00:00:00+00:00 [running]> on host 64bb4a2d8189
[2023-12-28T08:12:34.873+0000] {taskinstance.py:2481} INFO - Exporting env vars: AIRFLOW_CTX_DAG_OWNER='***' AIRFLOW_CTX_DAG_ID='etl_to_datalake' AIRFLOW_CTX_TASK_ID='process_datalake' AIRFLOW_CTX_EXECUTION_DATE='2022-11-12T00:00:00+00:00' AIRFLOW_CTX_TRY_NUMBER='1' AIRFLOW_CTX_DAG_RUN_ID='scheduled__2022-11-12T00:00:00+00:00'
[2023-12-28T08:12:35.017+0000] {taskinstance.py:2699} ERROR - Task failed with exception
Traceback (most recent call last):
  File "/home/airflow/.local/lib/python3.8/site-packages/airflow/models/taskinstance.py", line 433, in _execute_task
    result = execute_callable(context=context, **execute_callable_kwargs)
  File "/home/airflow/.local/lib/python3.8/site-packages/airflow/operators/python.py", line 199, in execute
    return_value = self.execute_callable()
  File "/home/airflow/.local/lib/python3.8/site-packages/airflow/operators/python.py", line 216, in execute_callable
    return self.python_callable(*self.op_args, **self.op_kwargs)
  File "/opt/airflow/dags/etl_to_datalake.py", line 76, in process_datalake
    load_query_result_to_bq(dict_config["sql"], dict_config["write_disposition"],
KeyError: 'write_disposition'
[2023-12-28T08:12:35.191+0000] {taskinstance.py:1138} INFO - Marking task as UP_FOR_RETRY. dag_id=etl_to_datalake, task_id=process_datalake, execution_date=20221112T000000, start_date=20231228T081231, end_date=20231228T081235
[2023-12-28T08:12:35.288+0000] {standard_task_runner.py:107} ERROR - Failed to execute job 11 for task process_datalake ('write_disposition'; 93)
[2023-12-28T08:12:35.596+0000] {local_task_job_runner.py:234} INFO - Task exited with return code 1
[2023-12-28T08:12:35.748+0000] {taskinstance.py:3281} INFO - 0 downstream tasks scheduled from follow-on schedule check
