[2024-01-08T04:40:13.185+0000] {taskinstance.py:1957} INFO - Dependencies all met for dep_context=non-requeueable deps ti=<TaskInstance: etl_to_dwh.fact_a scheduled__2023-12-27T00:00:00+00:00 [queued]>
[2024-01-08T04:40:13.322+0000] {taskinstance.py:1957} INFO - Dependencies all met for dep_context=requeueable deps ti=<TaskInstance: etl_to_dwh.fact_a scheduled__2023-12-27T00:00:00+00:00 [queued]>
[2024-01-08T04:40:13.322+0000] {taskinstance.py:2171} INFO - Starting attempt 1 of 3
[2024-01-08T04:40:13.531+0000] {taskinstance.py:2192} INFO - Executing <Task(PythonOperator): fact_a> on 2023-12-27 00:00:00+00:00
[2024-01-08T04:40:13.591+0000] {standard_task_runner.py:60} INFO - Started process 1175 to run task
[2024-01-08T04:40:13.627+0000] {standard_task_runner.py:87} INFO - Running: ['***', 'tasks', 'run', 'etl_to_dwh', 'fact_a', 'scheduled__2023-12-27T00:00:00+00:00', '--job-id', '12', '--raw', '--subdir', 'DAGS_FOLDER/etl_to_dwh.py', '--cfg-path', '/tmp/tmpta86ojas']
[2024-01-08T04:40:13.629+0000] {standard_task_runner.py:88} INFO - Job 12: Subtask fact_a
[2024-01-08T04:40:14.129+0000] {task_command.py:423} INFO - Running <TaskInstance: etl_to_dwh.fact_a scheduled__2023-12-27T00:00:00+00:00 [running]> on host 6d1c1d696e23
[2024-01-08T04:40:14.853+0000] {taskinstance.py:2481} INFO - Exporting env vars: AIRFLOW_CTX_DAG_OWNER='***' AIRFLOW_CTX_DAG_ID='etl_to_dwh' AIRFLOW_CTX_TASK_ID='fact_a' AIRFLOW_CTX_EXECUTION_DATE='2023-12-27T00:00:00+00:00' AIRFLOW_CTX_TRY_NUMBER='1' AIRFLOW_CTX_DAG_RUN_ID='scheduled__2023-12-27T00:00:00+00:00'
[2024-01-08T04:40:15.140+0000] {taskinstance.py:2699} ERROR - Task failed with exception
Traceback (most recent call last):
  File "/home/airflow/.local/lib/python3.8/site-packages/airflow/models/taskinstance.py", line 433, in _execute_task
    result = execute_callable(context=context, **execute_callable_kwargs)
  File "/home/airflow/.local/lib/python3.8/site-packages/airflow/operators/python.py", line 199, in execute
    return_value = self.execute_callable()
  File "/home/airflow/.local/lib/python3.8/site-packages/airflow/operators/python.py", line 216, in execute_callable
    return self.python_callable(*self.op_args, **self.op_kwargs)
  File "/opt/airflow/dags/etl_to_dwh.py", line 80, in process_dwh
    load_query_result_to_bq(dict_config["sql"], dict_config["write_disposition"],
  File "/opt/airflow/dags/etl_to_dwh.py", line 60, in load_query_result_to_bq
    raise e
  File "/opt/airflow/dags/etl_to_dwh.py", line 46, in load_query_result_to_bq
    bq_client = init_bq_client()
  File "/opt/airflow/dags/etl_to_dwh.py", line 35, in init_bq_client
    raise e
  File "/opt/airflow/dags/etl_to_dwh.py", line 24, in init_bq_client
    conn = Connection.get_connection_from_secrets(conn_id='dwh-creds')
  File "/home/airflow/.local/lib/python3.8/site-packages/airflow/models/connection.py", line 479, in get_connection_from_secrets
    raise AirflowNotFoundException(f"The conn_id `{conn_id}` isn't defined")
airflow.exceptions.AirflowNotFoundException: The conn_id `dwh-creds` isn't defined
[2024-01-08T04:40:15.166+0000] {taskinstance.py:1138} INFO - Marking task as UP_FOR_RETRY. dag_id=etl_to_dwh, task_id=fact_a, execution_date=20231227T000000, start_date=20240108T044013, end_date=20240108T044015
[2024-01-08T04:40:15.202+0000] {standard_task_runner.py:107} ERROR - Failed to execute job 12 for task fact_a (The conn_id `dwh-creds` isn't defined; 1175)
[2024-01-08T04:40:15.278+0000] {local_task_job_runner.py:234} INFO - Task exited with return code 1
[2024-01-08T04:40:15.342+0000] {taskinstance.py:3281} INFO - 0 downstream tasks scheduled from follow-on schedule check
