[2023-12-28T07:40:02.827+0000] {scheduler_job_runner.py:1586} WARNING - Marking task instance <TaskInstance: etl_to_datalake.process_datalake scheduled__2022-11-01T00:00:00+00:00 [queued]> stuck in queued as failed. If the task instance has available retries, it will be retried.
[2023-12-28T07:40:09.623+0000] {scheduler_job_runner.py:781} ERROR - Executor reports task instance <TaskInstance: etl_to_datalake.process_datalake scheduled__2022-11-01T00:00:00+00:00 [queued]> finished (failed) although the task says it's queued. (Info: None) Was the task killed externally?
